Workbook

Sheet 📊 Results
A1: Alpha ID | B1: Name | C1: Universe | D1: Sharpe | E1: Fitness | F1: TO % | G1: Max Corr | H1: Status | I1: Rejection Reason | J1: Date Submitted | K1: Notes | L1: Expression
A2: A1 | B2: Volatility Reversal | C2: TOP3000 | D2: 1.45 | E2: 0.78 | F2: 40 | G2: =IFERROR(MAX(Y2:AA2),"") -> 0 | H2: ❌ Rejected | I2: Fitness Block | K2: Signal decays rapidly. Pure vol signals fully arbitraged. | L2: -rank(ts_std_dev(returns,20))
A3: A2 | B3: Vol-Normalized Momentum | C3: TOP3000 | D3: 1.45 | E3: 0.78 | F3: 40 | G3: =IFERROR(MAX(Y3:AA3),"") -> 0 | H3: ❌ Rejected | I3: Fitness Block | K3: Simple delta has signal but Fitness <1.0. Needs second ingredient. | L3: -rank(ts_delta(close,5))
A4: A3 | B4: Vol-Ratio Reversal | C4: TOP3000 | D4: 1.02 | E4: 0.42 | F4: 42 | G4: =IFERROR(MAX(Y4:AA4),"") -> 0 | H4: ❌ Rejected | I4: Train/Test Overfit | K4: Train-Test gap >0.5 = disqualifying overfit. | L4: -rank(ts_corr(close,volume,10)/ts_std_dev(returns,20))
A5: A4 | B5: P/S Momentum | C5: TOP3000 | D5: 1.71 | E5: 1.37 | F5: 23.93 | G5: =IFERROR(MAX(Y5:AA5),"") -> 0 | H5: ✅ Submitted | K5: Template alpha. sales_ps most reliable fundamental found. | L5: -rank(ts_decay_linear(close/sales_ps,21)*rank(ts_delta(close,5)))
A6: A5 | B6: Bookvalue Momentum | C6: TOP3000 | D6: 1.07 | E6: 0.62 | F6: 22 | G6: =IFERROR(MAX(Y6:AA6),"") -> 0 | H6: ❌ Rejected | I6: 2021-2022 Collapse | K6: bookvalue_ps weaker than sales_ps. Distorted by buybacks. | L6: -rank(ts_decay_linear(close/bookvalue_ps,21)*rank(ts_delta(close,5)))
A7: A6 | B7: Sales Delta | C7: TOP3000 | D7: -0.35 | F7: 5.74 | G7: =IFERROR(MAX(Y7:AA7),"") -> 0 | H7: ❌ Rejected | I7: Dead Signal | K7: Pure fundamental momentum fails alone. Too slow, too low TO. | L7: -rank(ts_delta(sales_ps,63))
A8: A7 | B8: EV/EBITDA Reversion | C8: TOP3000 | D8: 1.19 | E8: 0.6 | F8: 10 | G8: =IFERROR(MAX(Y8:AA8),"") -> 0 | H8: ❌ Rejected | I8: 2021-2022 Collapse | K8: Train>>Test overfit. 2021/2022 both negative = dead. | L8: -ts_zscore(enterprise_value/ebitda,63)
A9: A8 | B9: Vol-Corr Momentum | C9: TOP3000 | D9: 0.6 | E9: 0.3 | F9: 40 | G9: =IFERROR(MAX(Y9:AA9),"") -> 0 | H9: ❌ Rejected | I9: Dead Signal | K9: No consistent signal. ts_corr highly unstable Train/Test. | L9: -rank(ts_corr(returns,volume,10))
A10: A9 | B10: Price Reversal × Volume | C10: TOP3000 | D10: 2.01 | E10: 1 | F10: 61.29 | G10: =IFERROR(MAX(Y10:AA10),"") -> 0 | H10: ✅ Submitted | K10: Best IS Sharpe submitted. Turnover high but passed Fitness=1.00. | L10: -rank(ts_delta(close,1)*ts_rank(volume,5))
A11: A10 | B11: Liquidity Momentum | C11: TOP3000 | D11: 1.93 | E11: 1.31 | F11: 28.66 | G11: =IFERROR(MAX(Y11:AA11),"") -> 0 | H11: ✅ Submitted | K11: current_ratio rare working fundamental. Delay 1 only. | L11: -rank(ts_decay_linear(current_ratio,21)*rank(ts_delta(close,5)))
A12: A11 | B12: Return Assets Momentum | C12: TOP3000 | D12: -0.12 | F12: 7.24 | G12: =IFERROR(MAX(Y12:AA12),"") -> 0 | H12: ❌ Rejected | I12: 2021-2022 Collapse | K12: Negative IS. return_assets COVID-distorted. | L12: -rank(ts_decay_linear(close/return_assets,21)*rank(ts_delta(close,20)))
A13: A12 | B13: EBIT/CAPEX Efficiency | C13: TOP3000 | D13: -0.13 | F13: 1.94 | G13: =IFERROR(MAX(Y13:AA13),"") -> 0 | H13: ❌ Rejected | I13: Dead Signal | K13: Negative IS. External PDF claimed 1.62 Sharpe — unverifiable. | L13: -rank(ebit/capex)
A14: A13 | B14: CLV Reversion | C14: TOP3000 | D14: 2.1 | E14: 0.96 | F14: 60 | G14: =IFERROR(MAX(Y14:AA14),"") -> 0 | H14: ❌ Rejected | I14: Fitness Block | K14: Best IS Sharpe overall but 60% TO creates structural Fitness ceiling. | L14: -rank(((2*close-high-low)/(high-low))*ts_rank(volume,5))
A15: A14 | B15: CLV+Volume/ADV20 | C15: TOP3000 | D15: 2.03 | E15: 0.99 | F15: 60 | G15: =IFERROR(MAX(Y15:AA15),"") -> 0 | H15: ❌ Rejected | I15: Fitness Block | K15: Same family as A13. 60% TO ceiling confirmed structural. | L15: -rank(((2*close-high-low)/(high-low))*volume/adv20)
A16: A15 | B16: ADV20 Reversion | C16: TOP3000 | D16: 2.08 | E16: 0.87 | F16: 85 | G16: =IFERROR(MAX(Y16:AA16),"") -> 0 | H16: ❌ Rejected | I16: Turnover Too High | K16: 85% turnover. Fitness penalizes >60% TO structurally. | L16: -rank(ts_delta(close,1)/adv20)
A17: A16 | B17: Price Delta × Volume v2 | C17: TOP3000 | D17: 1.81 | E17: 1.01 | F17: 48 | G17: =IFERROR(MAX(Y17:AA17),"") -> 0 | H17: ❌ Rejected | I17: Self-Correlation | K17: 0.96 vs A9. Minor delta change = same portfolio. | L17: -rank(ts_delta(close,2)*ts_rank(volume,10))
A18: A17 | B18: VWAP Zscore × Volume | C18: TOP3000 | D18: 2.1 | E18: 0.81 | F18: 63 | G18: =IFERROR(MAX(Y18:AA18),"") -> 0 | H18: ❌ Rejected | I18: Fitness Block | K18: 63% TO. Same ceiling as CLV family. Abandoned family. | L18: -rank(ts_zscore(close-vwap,20)*ts_rank(volume,5))
A19: A18 | B19: Current Ratio (Market Neut) | C19: TOP3000 | D19: 1.32 | E19: 1.07 | F19: 24 | G19: =IFERROR(MAX(Y19:AA19),"") -> 0 | H19: ❌ Rejected | I19: Self-Correlation | K19: 0.84 vs A10. Same variable = same correlation regardless of settings. | L19: -rank(ts_decay_linear(current_ratio,21)*rank(ts_delta(close,5)))
A20: A19 | B20: Momentum Up-Days | C20: TOP3000 | D20: 1.5 | E20: 0.78 | F20: 37 | G20: =IFERROR(MAX(Y20:AA20),"") -> 0 | H20: ❌ Rejected | I20: Fitness Block | K20: Signal exists but Fitness ceiling. 37% TO insufficient returns. | L20: rank(ts_sum(returns>0?1:0,250))
A21: A20 | B21: ts_arg_max Reversion | C21: TOP3000 | D21: 1.41 | E21: 0.87 | F21: 50 | G21: =IFERROR(MAX(Y21:AA21),"") -> 0 | H21: ❌ Rejected | I21: 2021-2022 Collapse | K21: 2021 Sharpe 0.56-0.73. Structural weakness in 2021. | L21: (vwap-close)/close/min(ts_decay_linear(rank(ts_arg_max(close,30)),2),0.20)
A22: A21 | B22: IV Regime + A9 Signal | C22: TOP3000 | D22: 1.94 | E22: 1.01 | F22: 35 | G22: =IFERROR(MAX(Y22:AA22),"") -> 0 | H22: ❌ Rejected | I22: Self-Correlation | K22: IV filter confirmed working (threshold 0.3). Inner signal = A9 = 0.85 corr. | L22: trade_when(ts_rank(implied_volatility_call_60,252)>0.3,-rank(ts_delta(close,1)*ts_rank(volume,5)),-1)
A23: A22 | B23: IV + CLV Filter | C23: TOP3000 | D23: 1.59 | E23: 0.75 | F23: 34 | G23: =IFERROR(MAX(Y23:AA23),"") -> 0 | H23: ❌ Rejected | I23: Fitness Block | K23: CLV without volume loses too much signal. Fitness 0.75. | L23: trade_when(ts_rank(implied_volatility_call_60,252)>0.3,-rank((2*close-high-low)/(high-low)),-1)
A24: A23 | B24: IV + Current Ratio Filter | C24: TOP3000 | D24: 1.96 | E24: 1.46 | F24: 22 | G24: =IFERROR(MAX(Y24:AA24),"") -> 0 | H24: ❌ Rejected | I24: Self-Correlation | K24: 0.9445 vs A10. Same var = same corr. Need different data source. | L24: trade_when(ts_rank(implied_volatility_call_60,252)>0.3,-rank(ts_decay_linear(current_ratio,21)*rank(ts_delta(close,5))),-1)
A25: A24 | B25: Debt/Equity Momentum | C25: TOP3000 | D25: -0.24 | F25: 16 | G25: =IFERROR(MAX(Y25:AA25),"") -> 0 | H25: ❌ Rejected | I25: 2021-2022 Collapse | K25: COVID stimulus broke leverage signals. 2021 Sharpe -1.19. | L25: -rank(ts_decay_linear(debt/equity,21)*rank(ts_delta(close,5)))
A26: A25 | B26: Debt/Assets Ratio | C26: TOP3000 | D26: -1.22 | F26: 2.64 | G26: =IFERROR(MAX(Y26:AA26),"") -> 0 | H26: ❌ Rejected | I26: 2021-2022 Collapse | K26: Negative every year. COVID distorted all leverage signals. | L26: -rank(debt/assets)
A27: A26 | B27: Social Buzz Momentum | C27: TOP3000 | D27: 1.4 | E27: 0.56 | F27: 48.63 | G27: =IFERROR(MAX(Y27:AA27),"") -> 0 | H27: ❌ Rejected | I27: Fitness Ceiling | K27: snt_buzz family: 10+ variants, IS Fitness ceiling 0.98. Permanently abandoned. Signal inverted (must use +rank not -rank). | L27: -rank(ts_decay_linear(scl12_buzz,21)*rank(ts_delta(close,5)))
A28: A27 | B28: OEY ts_rank | C28: TOP3000 | F28: 10 | G28: =IFERROR(MAX(Y28:AA28),"") -> 0 | H28: ❌ Rejected | I28: 2021-2022 Collapse | K28: operating_income unavailable or 2021-2022 collapse. Tutorial Sharpe unverifiable. | L28: -rank(ts_rank(operating_income/cap,250))
A29: A28 | B29: Range Momentum | C29: TOP3000 | D29: -0.08 | F29: 8 | G29: =IFERROR(MAX(Y29:AA29),"") -> 0 | H29: ❌ Rejected | I29: Dead Signal | K29: 2020 Sharpe -2.57. Extreme COVID vol sensitivity. | L29: rank(ts_mean(high-low,20)/ts_mean(high-low,252))
A30: A29 | B30: Open-Close Reversion | C30: TOP3000 | D30: -1.22 | F30: 26 | G30: =IFERROR(MAX(Y30:AA30),"") -> 0 | H30: ❌ Rejected | I30: Dead Signal | K30: Consistently negative every year. No persistent cross-sectional signal. | L30: -rank(ts_mean(close-open,10))
A31: A30 | B31: Earnings Revision Filter | C31: TOP3000 | D31: -0.57 | F31: 12 | G31: =IFERROR(MAX(Y31:AA31),"") -> 0 | H31: ❌ Rejected | I31: Dead Signal | K31: 56% coverage kills sub-universe Sharpe. Analyst fields too sparse. | L31: trade_when(snt1_d1_netearningsrevision>0,rank(ts_delta(close,5)),-1)
A32: MC3 | B32: Value Rank ts_rank(252) | C32: TOP3000 | D32: 1.89 | E32: 1.66 | F32: 10.44 | G32: =IFERROR(MAX(Y32:AA32),"") -> 0 | H32: ✅ Submitted | J32: 05/04/2026 | K32: ts_rank(252) rescued value signal from 2020 crash. Near-zero corr with all submitted. Alpha 11. | L32: -rank(ts_rank(mdl177_garpanalystmodel_qgp_vfpriceratio,252))
A33: M6 | B33: CashFlow/EV ts_rank(252) | C33: TOP3000 | D33: 1.72 | E33: 1.22 | F33: 9.06 | G33: =IFERROR(MAX(Y33:AA33),"") -> 0 | H33: ✅ Submitted | J33: 05/04/2026 | K33: Most consistent yearly profile in tracker — all 5 years positive, min 1.41. Alpha 12. ts_rank(252) pattern confirmed for Model value family. | L33: -rank(ts_rank(mdl177_2_sensitivityfactor400_ttmocfev,252))
A34: Z1 | B34: Analyst Stock Rank Naked | C34: TOP3000 | D34: 0.36 | E34: 0.19 | F34: 4.09 | G34: =IFERROR(MAX(Y34:AA34),"") -> 0 | H34: ❌ Rejected | I34: 2021-2022 Collapse | K34: 2021/2022 regime failure. A4 template also failed (2021=0.00, 2022=-0.41). Two-test rule exhausted. Abandoned. | L34: -rank(snt1_d1_stockrank)
A35: Z2 | B35: scl12_sentiment Naked | C35: TOP3000 | D35: 0.58 | E35: 0.08 | F35: 86.03 | G35: =IFERROR(MAX(Y35:AA35),"") -> 0 | H35: ❌ Rejected | I35: Fitness Ceiling | K35: 86% TO makes Fitness mathematically impossible. Would need 93% returns for Fitness 1.0 at this Sharpe. Dead. | L35: -rank(scl12_sentiment)
A36: Z3 | B36: snt_buzz_ret Naked | C36: TOP3000 | D36: -0.27 | E36: -0.03 | F36: 62.83 | G36: =IFERROR(MAX(Y36:AA36),"") -> 0 | H36: ❌ Rejected | I36: Dead Signal | K36: Negative both signs. Flipped sign also dead. Abandoned. | L36: -rank(snt_buzz_ret)
A37: Z4 | B37: snt_social_value Naked | C37: TOP3000 | D37: -0.61 | E37: -0.13 | F37: 47.58 | G37: =IFERROR(MAX(Y37:AA37),"") -> 0 | H37: ❌ Rejected | I37: Dead Signal | K37: Negative both signs. Flipped also dead. Abandoned. | L37: -rank(snt_social_value)
A38: M1 | B38: Value-to-Price Rank Naked | C38: TOP3000 | D38: 1.09 | E38: 1.05 | F38: 3.07 | G38: =IFERROR(MAX(Y38:AA38),"") -> 0 | H38: ❌ Rejected | I38: Sharpe Below Cutoff | K38: IS Sharpe 1.09 below 1.25 cutoff. Sub-universe Sharpe 0.46 below 0.47 cutoff. Led to MC3 discovery. | L38: -rank(mdl177_garpanalystmodel_qgp_vfpriceratio)
A39: M4 | B39: CashFlow/EV Naked | C39: TOP3000 | D39: 0.66 | E39: 0.5 | F39: 2.64 | G39: =IFERROR(MAX(Y39:AA39),"") -> 0 | H39: ❌ Rejected | I39: 2021-2022 Collapse | K39: 2020 collapse -2.09. ts_rank(252) fix led to M6 submission. | L39: -rank(mdl177_2_sensitivityfactor400_ttmocfev)
A40: DV1 | B40: Current Earnings Yield ts_rank | C40: TOP3000 | D40: 1.04 | E40: 0.68 | F40: 9.46 | H40: ❌ Rejected | I40: Fitness Below Threshold | K40: IS 1.04, Fitness 0.68. All years positive except 2023 flat. Below Fitness threshold. | L40: -rank(ts_rank(mdl177_2_deepvaluefactor_curep,252))
...

Sheet WQ_Brain_Tracker_Session20
A1: Field | B1: Description | C1: Category | D1: Status | E1: Signal Strength | F1: Notes
A2: close | B2: Daily closing price | C2: Price-Volume | D2: ✅ In Use | E2: Strong | F2: Foundation of all PV signals. 60% TO ceiling as primary.
A3: volume | B3: Daily trading volume | C3: Price-Volume | D3: ✅ In Use | E3: Strong | F3: Use as ts_rank for robustness. High TO when primary.
A4: returns | B4: Daily returns | C4: Price-Volume | D4: ✅ In Use | E4: Strong | F4: Used in vol calculations and momentum signals.
A5: high | B5: Daily high price | C5: Price-Volume | D5: ✅ In Use | E5: Strong | F5: Used in CLV and range calculations.
A6: low | B6: Daily low price | C6: Price-Volume | D6: ✅ In Use | E6: Strong | F6: Used in CLV and range calculations.
A7: open | B7: Daily open price | C7: Price-Volume
A8: vwap | B8: Volume-weighted average price | C8: Price-Volume | D8: ⚪ Backlog | E8: Weak | F8: 60% TO ceiling blocks Fitness. Signal exists.
A9: adv20 | B9: Average daily volume over 20 days | C9: Price-Volume | D9: ⚪ Backlog | E9: Weak | F9: Better as normalizer than primary signal. 85% TO as primary.
A10: current_ratio | B10: Current Ratio | C10: Fundamental | D10: ✅ In Use | E10: Strong | F10: Liquidity-based. Works because not COVID-distorted. Delay 1 only.
A11: sales_ps | B11: Sales per Share (Quarterly) | C11: Fundamental | D11: ✅ In Use | E11: Strong | F11: Template alpha. Best fundamental found. No COVID distortion.
A12: scl12_buzz | B12: relative sentiment volume | C12: Social Media | D12: ❌ Abandoned | E12: Weak | F12: A26 family abandoned. 3 fix variants all failed. Fitness ceiling 0.56.
A13: snt_buzz | B13: Negative relative sentiment volume measure for current day, with missing values filled as 0 | C13: Social Media | D13: ❌ Abandoned | E13: Dead | F13: Signal inverted. 10+ variants tested. IS Fitness ceiling 0.98. Permanently exhausted. Do not revisit.
A14: snt_buzz_bfl | B14: Negative relative sentiment volume measure for current day, with missing values filled as 1 | C14: Social Media | D14: ❌ Abandoned | E14: Dead | F14: Negative IS Sharpe in all variants. Dead signal.
A15: scl12_sentiment | B15: sentiment | C15: Social Media | D15: ❌ Abandoned | E15: Dead | F15: 86% TO creates mathematical Fitness ceiling. IS Fitness 0.08 naked. Abandoned Session 11.
A16: snt_value | B16: Negative sentiment score/indicator for current day, with missing values filled as 0 | C16: Social Media | D16: ❌ Abandoned | E16: Dead | F16: Confirmed dead (negative Sharpe both signs). Previously listed as Z3 — reclassified to Z5 (skip if quota is limited). Do not re-queue.
A17: snt1_d1_stockrank | B17: Rank (0-100) based on equity-style factors, where higher values reflect a stronger buy signal and lower values a sell signal | C17: Sentiment / Analyst | D17: ❌ Abandoned | E17: Dead | F17: Two-test exhausted: naked failed 2021/2022, A4 template also failed. Abandoned Session 11.
A18: implied_volatility_call_60 | B18: Implied volatility of the at-the-money call for the stock with an expiration 60 calendar days from the measurement date | C18: Options - Volatility | D18: 🟠 Test Soon | E18: Medium | F18: IV filter confirmed at >0.3. Need new uncorrelated inner signal.
A19: snt_social_value | B19: Z-score of sentiment | C19: Social Media | D19: ❌ Abandoned | E19: Dead | F19: Negative both signs. Abandoned Session 11.
A20: snt_social_volume | B20: Normalized tweet volume | C20: Social Media | D20: ❌ Abandoned | E20: Dead | F20: Duplicate result with snt_value confirmed dead. Abandoned Session 11.
A21: scl12_buzzvec | B21: Vector representing the volume of social media sentiment/mentions related to the instrument | C21: Social Media
A22: snt_buzz_ret | B22: negative return of relative sentiment volume | C22: Social Media | D22: ❌ Abandoned | E22: Dead | F22: Negative both signs. Abandoned Session 11.
A23: scl12_sentvec | B23: Vector representing the sentiment score (bullish/bearish/neutral) derived from social media data for the instrument | C23: Social Media
A24: scl12_typevec | B24: Vector containing the type indices identifying the categories of instruments in the dataset | C24: Social Media
A25: scl12_alltype_buzzvec | B25: sentiment volume | C25: Social Media
A26: snt_value_fast_d1 | B26: Negative sentiment score/indicator for current day, with missing values filled as 0 | C26: Social Media
A27: snt_buzz_fast_d1 | B27: Negative relative sentiment volume measure for current day, with missing values filled as 0 | C27: Social Media
A28: scl12_sentiment_fast_d1 | B28: sentiment | C28: Social Media
A29: scl12_buzz_fast_d1 | B29: relative sentiment volume | C29: Social Media
A30: snt_buzz_bfl_fast_d1 | B30: Negative relative sentiment volume measure for current day, with missing values filled as 1 | C30: Social Media
A31: scl12_alltype_sentvec | B31: sentiment | C31: Social Media
A32: scl12_alltype_typevec | B32: instrument type index | C32: Social Media
A33: snt_buzz_ret_fast_d1 | B33: negative return of relative sentiment volume | C33: Social Media
A34: snt1_d1_analystcoverage | B34: Number of analysts providing an earnings estimate for the stock | C34: Sentiment / Analyst
... A1064: fnd6_newqeventv110_pncwippq | B1064: Core Pension w/o Interest Adjustment Pretax Preliminary | C1064: Fundamental
A1065: pcr_vol_10 | B1065: Ratio of total put option volume to call option volume for options expiring in 10 days, reflecting very short-term sentiment flow | C1065: Options - Analytics | D1065: 🔴 Abandon | E1065: Dead | F1065: Put-call ratio tested — no meaningful signal found.
A1066: enterprise_value | B1066: Enterprise Value | C1066: Fundamental | D1066: 🔴 Abandon | E1066: Weak | F1066: COVID killed EV/EBITDA relationship. 2021+2022 both negative.
A1067: debt | B1067: Debt | C1067: Fundamental | D1067: 🔴 Abandon | E1067: Dead | F1067: COVID stimulus inverted all leverage signals. Never use.
A1068: ebit | B1068: Earnings Before Interest and Taxes | C1068: Fundamental | D1068: 🔴 Abandon | E1068: Dead | F1068: Negative IS. External PDF Sharpe unverifiable.
A1069: bookvalue_ps | B1069: Book Value Per Share | C1069: Fundamental | D1069: 🔴 Abandon | E1069: Weak | F1069: Distorted by share buybacks. Weaker than sales_ps.
...

Sheet 📈 Dashboard
A1: 🧠 WorldQuant BRAIN — Research Dashboard
A3: 🏆 IQC 2026 Status
A4: D1 Score | B4: 8526 | C4: Total Tested | D4: =COUNTA('📊 Results'!A:A)-1 -> 164
A5: IQC Stage 1 Rank | C5: ✅ Submitted | D5: =COUNTIF('📊 Results'!H:H,"✅ Submitted") -> 13
A6: Challenge Score | B6: 13851 | C6: ❌ Rejected | D6: =COUNTIF('📊 Results'!H:H,"❌ Rejected") -> 121
A7: Challenge Rank | B7: 8017 | C7: Best Sharpe | D7: =MAX('📊 Results'!D:D) -> 2.1
A8: Deadline | B8: May 18, 2026 | C8: Best Fitness | D8: =MAX('📊 Results'!E:E) -> 1.88
A9: Days Remaining | B9: =DATE(2026,5,19)-TODAY() -> 5 | C9: Fields Tracked | D9: =COUNTA(WQ_Brain_Tracker_Session20!A:A)-1 -> 1731
A11: 📋 Submit Queue (highest score first)
A12: Date | B12: Alpha | C12: Score Δ | D12: Description
A13: ✅ May 9 | B13: NEW-5b | C13: +552 | D13: TOP500 DV5 — DONE
A14: ✅ May 9/10 | B14: VA-1 | C14: +238 | D14: TOP3000 valanalystmodel_qva_incstmt — DONE
A15: ✅ May 10 | B15: NEW-3b | C15: +340 | D15: TOP500 ttmocfev naked — DONE
A16: ✅ May 12 | B16: ZY2OXdKQ 🆕 | C16: +238 | D16: TOP500 rel5ybp — agent find, corr 0.55 — DONE
A17: ✅ May 13 | B17: npnMdNNz 🆕 | C17: +396 | D17: TOP3000 FANGMA VMM11 ts_zscore — DONE
A18: May 14 | B18: 9q90GOld 🔥 | C18: +639 | D18: 🔥 BEST SCORE EVER — TOP200 FANGMA VMM11 ts_rank, corr 0.24. Submit immediately.
A19: May 15 | B19: e7nobL6O 🆕 | C19: TBC | D19: TOP3000 FANGMA VMM11 ts_rank — corr 0.54. Check score on platform first.
A20: May 16 | B20: E5qJ5qr0 🆕 | C20: TBC | D20: TOP3000 days_to_cover ts_rank — corr 0.36. Check score on platform first.
A21: May 17 | B21: MPKN7bXr 🆕 | C21: +37 | D21: TOP500 pdy — fallback. Swap if d1v10 finds better.
A22: ⚠️ Benched | B22: VMA-2 +66, T5K-2 +67, RV-1b +66, NEW-9b +50, Alt-1 +27, DV3b +4 | D22: No slots — use only if queue alpha scores negative
A23: ❌ Dead | B23: T1K-3 corr 0.72 | T5K-4 Fit 0.91 | NEW-7b score -8 | T5K-5 score -304 | onloan_conc sharpe -0.29 | sht_int sharpe 0.54 | D23: All confirmed dead
A27: ⚡ Key Rules
A28: Submit order | B28: Descending score change — NOT IS Sharpe order
A29: Score change | B29: Positive = submit | Negative = reject permanently
A30: Corr threshold | B30: Max self-corr < 0.70 vs all submitted alphas
A31: Fitness floor | B31: ≥ 1.00 (Sharpe ≥ 1.25, TO 1–70%, passed ≥ 6/7)
A32: Variable names | B32: Always verify from Fields Tracker — never guess
A33: TOP500 universe | B33: Usually corr 0.28–0.65 vs TOP3000 — test after any TOP3000 pass
A34: TOP1000 universe | B34: Usually corr 0.73–0.83 — skip unless variable is very different
A35: mdl177_2 prefix | B35: Same family as mdl177 — corr 0.90+ — not an independent signal
A37: 🔬 Research Backlog (Next Session)
A38: Priority | B38: Family | C38: Fields to Test | D38: Rationale
A39: 1 — Running | B39: ❌ DEAD — industryrrelativevaluefactor (double-r) | C39: ALL 8 fields tested — ALL fitness < 1.00. Entire family dead. | D39: d1v10 complete. Every field below fitness threshold. Do not retest.
A40: 2 — Pending | B40: ✅ DONE — fangma_vmm11 tune variants | C40: npnMdNNz (zscore +396), 9q90GOld (ts_rank TOP200 +639), e7nobL6O (ts_rank TOP3000 TBC) | D40: Tune complete. 9q90GOld is best score ever found (+639).
A41: 1 — In d1v11 | B41: valanalystmodel siblings | C41: qva_fwdep, qva_bp, qva_revs, qva_divy, qva_epssurp, qva_valuation | D41: VA-1 scored +238 — siblings in d1v11 batch
A42: 2 — In d1v11 | B42: vma2 siblings | C42: vma2_ma, vma2_ma_ee, vma2_ma_em, vma2_ma_pm | D42: VMA-2 scored +66 — siblings in d1v11 batch
A43: 3 — In d1v11 | B43: 5yr relativevalue siblings | C43: rel5yep, rel5yocfp, rel5yfcfp, rel5ysp, rel5ycoreepsp | D43: rel5ybp +238, rel5yfwdep +385 — more siblings in d1v11
A44: 🔥 HOT — In d1v11 | B44: fangma siblings (gpam/rvm/mam/emf/dvm) | C44: gpam11/10/5, rvm6/1, mam16/11/6/5, emf25/20/15/4, dvm4/1 | D44: vmm11 gave +396/+639 — siblings completely untested. Highest priority.
A45: 4 — In d1v11 | B45: valueanalystmodel (≠ valanalystmodel) | C45: qva_incstmt, qva_finstmt, qva_epmodule, qva_pegy, qva_earnval | D45: DIFFERENT model from valanalystmodel — mdl177_valueanalystmodel prefix. Untested.
A46: 5 — In d1v11 | B46: earningmomentumfactor400 | C46: rev6, numrevy1, numrevq1, epsrm, fqsurs_std, salesurp, stockrating, y1aepsg, cvfy1eps, fcfroey1p | D46: Fresh analyst momentum family — completely untested. 10 candidates.
...
